Workbook

Sheet Carátula
D8: UDB LEGISLACIÓN Y ECONOMÍA
D10: Economía
D11: Plan de Negocios
D12: Grupo 4
D13: Venta de mochilas tácticas
D15: Legajo | E15: Apellido | F15: Nombres
C17: 1 | D17: 2036563 | E17: García | F17: Patricio Lionel
C18: 2 | D18: 2139303 | E18: Noblia | F18: Lucas Iñaki
C19: 3
C20: 4
D22: Grupo N° | E22: 4
D23: Docente | E23: Ing. Juan José Cosentino
D24: Aux Docente | E24: Leonardo Douglas Costucica
D25: Curso | E25: Z3522
D26: Año | E26: 2° CUATRIMESTRE 2024

Sheet Consideraciones
C3: Consideraciones Generales
C5: Tasa Bancaria | D5: 0.45
C6: Tasa de oportunidad de los socios | D6: 0.65
C7: Dias por mes Fabricación | D7: 22
C8: Dias por mes Administración | D8: 22
C9: Meses por año | D9: 12
C10: Dias del año | D10: 365
C11: Horas laborables diarias FAB | D11: 8
C12: Horas laborables diarias ADM | D12: 8
C13: Tipo de Cambio: u$s 1 = | D13: 1200
C14: Inflación anual | D14: 0
C15: IVA | D15: 0.21
C16: Impuesto a las Ganancias | D16: 0.35
C17: Cargas Sociales | D17: 0.6
C20: Celdas con Formulas no editables
C21: Celdas editables

Sheet Costos Variables de Fabricación
C3: Costo Variables Fabricación
C5: Mano de Obra Directa | I5: Materia Prima (Unidad de medida de compra)
C6: Puesto | D6: Sueldo Mesual Bruto | E6: Cantidad de personal | F6: Total | I6: Detalle Materia Prima | J6: Precio | K6: Unidad de medida
C7: Personal de corte | D7: 600000 | E7: 5 | F7: =D7*E7 -> 3000000 | I7: Cierre Cadena | J7: 5000 | K7: metro
C8: Costurero | D8: 1000000 | E8: 1 | F8: =D8*E8 -> 1000000 | I8: Deslizador | J8: 10000 | K8: u
F9: =D9*E9 -> 0 | I9: Tela Cordura Negra | J9: 2300 | K9: metro
F10: =D10*E10 -> 0 | I10: Escaleras de plastico | J10: 15000 | K10: u
F11: =D11*E11 -> 0
C12: Total Mensual | E12: =SUM(E7:E11) -> 6 | F12: =SUM(F7:F11) -> 4000000
C13: Total Sueldo Fabril Anual | F13: =12*F12 -> 48000000
I14: Materia Prima por Producto | J14: Consumo x unidad | K14: Precio | L14: Costo
C15: Total Aguinaldo Anual | F15: =F12 -> 4000000 | I15: =IF(I7="","",I7) -> Cierre Cadena | J15: 1 | K15: =+J7 -> 5000 | L15: =J15*K15 -> 5000
I16: =IF(I8="","",I8) -> Deslizador | J16: 1 | K16: =+J8 -> 10000 | L16: =J16*K16 -> 10000
C17: Total de cargas sociales del empleador | F17: =Consideraciones!$D$17*(F13+F15) -> 31200000 | I17: =IF(I9="","",I9) -> Tela Cordura Negra | J17: 1 | K17: =+J9 -> 2300 | L17: =J17*K17 -> 2300
I18: =IF(I10="","",I10) -> Escaleras de plastico | J18: 1 | K18: =+J10 -> 15000 | L18: =J18*K18 -> 15000
C19: Calculo de Viaticos y refrigerio: | I19: =IF(I11="","",I11) | J19: 1 | K19: =+J11 | L19: =J19*K19 -> 0
C20: Costo Viatico y refrigerio x persona y por día | F20: 0
C21: Personas | F21: =+E12 -> 6 | G21: Operarios | I21: Costo unitario Materia Prima | L21: =SUM(L15:L19) -> 32300 | M21: $ /Unidad
C22: Dias por mes | F22: =+Consideraciones!D7 -> 22 | G22: Días / Mes | I22: Producción Terminada | L22: =+Mercado!H22 -> 3600 | M22: Unidades
C23: Meses por año | F23: =+Consideraciones!D9 -> 12 | G23: Meses / Año | I23: Costo Total Materia Prima | L23: =+L22*L21 -> 116280000
C24: Total Anual Viaticos y refrigerios | F24: =+F20*F21*F22*F23 -> 0
I25: Costo Variable Total de Fabricación | L25: =+L23+F26 -> 199480000
C26: COSTO TOTAL MANO DE OBRA DIRECTA | F26: =+F24+F17+F15+F13 -> 83200000 | I26: Costo Variable Unitario de Fabricación | L26: =+L21+F27 -> 55411.111 | M26: $ /Unidad
C27: COSTO UNITARIO MANO DE OBRA DIRECTA | F27: =F26/Mercado!H22 -> 23111.111 | G27: $ / Unidad | I27: Incidencia del costo sobre el precio de venta | L27: =+L26/Mercado!F18 -> 0.69263889

Sheet Mercado
C3: Mercado
C5: Nombre del Mercado Potencial (1) | E5: Mercado Potencial (Q) | F5: Mercado Meta (2) (%) | G5: Mercado Meta (Q) | I5: Ventas destinadas al mercado Mayorista (%) | J5: Ventas destinadas al mercado Minorista (%) | K5: Total (%)
C6: Mochilas Tacticas | E6: =500*12*4 -> 24000 | F6: 0.15 | G6: =E6*F6 -> 3600 | I6: 1 | J6: 0 | K6: 1
C9: Mix de Productos
C10: Nombre del Producto | E10: Cantidad Vendida | F10: Precio de Venta Minorista | G10: Precio de Venta Mayorista | H10: % Participación por producto
C11: Mochila Tactica | E11: =G6 -> 3600 | F11: 0 | G11: 80000 | H11: =+E11/$E$14 -> 1
H12: =+E12/$E$14 -> 0
H13: =+E13/$E$14 -> 0
E14: =+SUM(E11:E13) -> 3600 | F14: =+AVERAGE(F11:F13) -> 0 | G14: =+AVERAGE(G11:G13) -> 80000 | H14: =+IF(G6-E14<>0,"La cantidad vendida debe ser igual a la cantidad de mercado meta","")
F15: Calcular promedio ponderado de precios
C17: Vida Util | D17: Precio de Venta Mayorista | E17: Precio de Venta Minorista | F17: MIX de Precios | G17: Crecimiento del mercado | H17: Cantidad Vendida | I17: Capacidad instalada
C18: 1 | D18: =+G14 -> 80000 | E18: =+F14 -> 0 | F18: =+D18*$I$6+E18*$J$6 -> 80000 | G18: 0.3 | H18: =+E14/4 -> 900 | I18: =+H18/$G$6 -> 0.25
C19: 2 | D19: =+D18*(1+Consideraciones!$D$14) -> 80000 | E19: =+E18*(1+Consideraciones!$D$14) -> 0 | F19: =+D19*$I$6+E19*$J$6 -> 80000 | G19: 0.4 | H19: =+H18*(1+G19) -> 1260 | I19: =+H19/$G$6 -> 0.35
C20: 3 | D20: =+D19*(1+Consideraciones!$D$14) -> 80000 | E20: =+E19*(1+Consideraciones!$D$14) -> 0 | F20: =+D20*$I$6+E20*$J$6 -> 80000 | G20: 0.4 | H20: =+H19*(1+G20) -> 1764 | I20: =+H20/$G$6 -> 0.49
C21: 4 | D21: =+D20*(1+Consideraciones!$D$14) -> 80000 | E21: =+E20*(1+Consideraciones!$D$14) -> 0 | F21: =+D21*$I$6+E21*$J$6 -> 80000 | G21: 0.4 | H21: =+H20*(1+G21) -> 2469.6 | I21: =+H21/$G$6 -> 0.686
C22: 5 | D22: =+D21*(1+Consideraciones!$D$14) -> 80000 | E22: =+E21*(1+Consideraciones!$D$14) -> 0 | F22: =+D22*$I$6+E22*$J$6 -> 80000 | G22: =+H22/H21-1 -> 0.45772595 | H22: =+G6 -> 3600 | I22: =+H22/$G$6 -> 1
H23: =+IF(H22>G6,"Cantidad a vender mayor al mercado meta","")
C25: Proyección estimada de ventas del producto en los proximos 5 años
C26: Teniendo en cuenta que el porcentaje de ventas mayoristas es del 70% y de ventas minoristas el 30% de lo producido, y un aumento cada 3 meses del 12%
C27: Año | D27: Periodo | E27: Unidades vendidas | F27: Precio Mayorista | G27: Ventas Mayorista | H27: Precio Minorista | I27: Ventas Minorista | J27: Facturacion Mayorista | K27: Facturacion Minorista | L27: Facturacion Total
C28: 1 | D28: 1-3 meses | E28: 50 | F28: $80.000 | G28: 35 | H28: $38,000.00 | I28: 15 | J28: $700,000.00 | K28: $570,000.00 | L28: $1,270,000.00
C29: 1 | D29: 4-6 meses | E29: 62 | F29: $85.000 | G29: 43 | H29: $42,560.00 | I29: 19 | J29: $963,200.00 | K29: $808,640.00 | L29: $1,771,840.00
C30: 1 | D30: 7-9 meses | E30: 78 | F30: $90.000 | G30: 55 | H30: $47,667.00 | I30: 23 | J30: $1,379,840.00 | K30: $1,096,341.00 | L30: $2,476,181.00
C31: 1 | D31: 10-12 meses | E31: 100 | F31: $100.000 | G31: 70 | H31: $53,400.00 | I31: 30 | J31: $2,030,000.00 | K31: $1,602,000.00 | L31: $3,632,000.00
C32: Aclaracion: el segundo año comenzara con los mismos precios y se mantendra durante 6 meses para luego realizar un aumento del 9%
C33: 2 | D33: 1-6 meses | E33: 150 | F33: $100.000 | G33: 105 | H33: $53,400.00 | I33: 45 | J33: $3,045,000.00 | K33: $2,403,000.00 | L33: $5,448,000.00
C34: 2 | D34: 7-12 meses | E34: 225 | F34: $109.000 | G34: 158 | H34: $58,200.00 | I34: 67 | J34: $5,008,600.00 | K34: $3,899,400.00 | L34: $8,908,000.00
C35: Aclaracion: a partir del 3er año se produciran 300 unidades mensuales, lo que se mantendra durante el 4to y 5to año, iniciando este periodo con un aumento del 9%
C36: 3,4 y 5 | D36: 1-36 meses | E36: 300 | F36: $100.000 | G36: 210 | H36: $63,500.00 | I36: 90 | J36: $7,245,000.00 | K36: $5,715,000.00 | L36: $12,960,000.00
C38: (1) Mercado potencial: Es el mercado donde se encuentra instalado nuestro producto o servicio
C39: (2) Mercado meta: es parte del mercado potencial o disponible que la empresa decide captar

Sheet Gastos Fijos de Fabricación
C3: Costo Fijos Fabricación
C5: Mano de Obra Indirecta | H5: Consumo Energetico fabril
C6: Puesto | D6: Sueldo Mesual Bruto | E6: Cantidad de personal | F6: Total | H6: Horas laborables diarias | I6: =+Consideraciones!D11 -> 8 | K6: Tipo de energia utilizada | L6: Electricidad
D7: 0 | E7: 0 | F7: =D7*E7 -> 0 | P7: Gas
D8: 0 | E8: 0 | F8: =D8*E8 -> 0 | H8: Cantidad de máquinas eléctricas | I8: 5 | P8: Electricidad
D9: 0 | E9: 0 | F9: =D9*E9 -> 0 | H9: Cantidad de máquinas a Gas | I9: 0 | P9: Ambos
C10: Total Mensual | E10: =SUM(E7:E9) -> 0 | F10: =SUM(F7:F9) -> 0 | P10: Ninguno
C11: Total Sueldo Fabril Anual | F11: =12*F10 -> 0 | H11: $ (KW HORA x Maquina) | I11: 40 | K11: Consumo KW x hora x Maquina | L11: 8.9
H12: $ (M3 HORA x Maquina) | I12: 180 | K12: Consumo M3 x hora x Máquina | L12: 2.3
C14: Total Aguinaldo Anual | F14: =F10 -> 0 | H14: Consumo total energía eléctrica (anual) | L14: =IF($I$11="",0,I8*I11*L11*Consideraciones!D11*Consideraciones!D7) -> 313280
H15: Consumo total gas (anual) | L15: =IF(I12="",0,I9*I12*L12*Consideraciones!$D$11*Consideraciones!$D$7) -> 0
C17: Total de cargas sociales del empleador | F17: =Consideraciones!D17*(F14+F11) -> 0 | H17: Consumo de Energia Total Anual: | L17: =IF(L6="Ninguno",0,(L14+L15)*Consideraciones!D9) -> 3759360
C19: Calculo de Viaticos y refrigerio: | H19: Otros Gastos de Fabricación
C20: Costo Viatico y refrigerio x persona y por día | F20: 0 | H20: Detalle | L20: Costo
C21: Personas | F21: 6 | H21: Alquiler | L21: 3000000 | M21: $ / Año
C22: Dias por mes | F22: =+Consideraciones!D7 -> 22 | H22: Repuestos y Lubricantes | L22: 50000 | M22: $ / Año
C23: Meses por año | F23: =+Consideraciones!D9 -> 12 | M23: $ / Año
C24: Total Anual Viaticos y refrigerios | F24: =+F20*F21*F22*F23 -> 0 | L24: 0 | M24: $ / Año
C25: Costo Total Mano de Obra indirecta | F25: =+F24+F17+F14+F11 -> 0 | H25: Otros Gastos de Fabricación | L25: =SUM(L21:L24) -> 3050000
H27: Gastos Fabricación Fijos | L27: =+L25+L17+F25 -> 6809360

Sheet Gastos de Comercialización
C3: Gastos Comercialización
C5: Gastos Comercialización Fijos | H5: Gastos Comercialización Variables
C6: Puesto | D6: Sueldo Mesual Bruto | E6: Cantidad de personal | F6: Total | J6: Local | K6: =+IF($E$7="","",0.4%)
F7: =E7*D7 -> 0 | J7: Viajante | K7: =+IF($E$7="","",0.8%) | L7: Gastos Comerciales
C8: Total Mensual | F8: =SUM(F7) -> 0 | H8: Año 1 | I8: 0.04 | J8: Ingresos Brutos | K8: Comisión Vendedor | L8: Variables Unitarios
C9: Total Sueldo Comercial Anual | F9: =F8*12 -> 0 | H9: Precio al publico | I9: =+Mercado!E18 -> 0 | J9: =+I9*$I$8 -> 0 | K9: =IF($E$7="","",$K$6*I9) | L9: =IF($K$6="",J9,+K9+J9) -> 0
H10: Precio x mayor | I10: =+Mercado!D18 -> 80000 | J10: =+$I$8*I10 -> 3200 | K10: =IF($E$7="","",$K$7*I10) | L10: =IF($K$7="",J10,+K10+J10) -> 3200
C11: Total Aguinaldo Anual | F11: =F8 -> 0 | H11: Precio Promedio Ponderado (PPP) | I11: =+Mercado!F18 -> 80000 | L11: =+Mercado!$J$6*L9+Mercado!$I$6*L10 -> 3200
L12: =+L11/I11 -> 0.04
C13: Total de cargas sociales del empleador | F13: =Consideraciones!D17*(F11+F9) -> 0 | H13: Año 2
H14: Precio al publico | I14: =+Mercado!E19 -> 0 | J14: =+I14*$I$8 -> 0 | K14: =IF($E$7="","",$K$6*I14) | L14: =IF($K$6="",J14,+K14+J14) -> 0
C15: Calculo de Viaticos y refrigerio: | H15: Precio x mayor | I15: =+Mercado!D19 -> 80000 | J15: =+$I$8*I15 -> 3200 | K15: =IF($E$7="","",$K$7*I15) | L15: =IF($K$7="",J15,+K15+J15) -> 3200
C16: Costo Viatico y refrigerio x persona y día | F16: 0 | H16: Precio Promedio Ponderado (PPP) | I16: =+Mercado!F19 -> 80000 | L16: =+Mercado!$J$6*L14+Mercado!$I$6*L15 -> 3200
C17: Días por mes | F17: =+Consideraciones!D8 -> 22 | L17: =+L16/I16 -> 0.04
C18: Meses por año | F18: =+Consideraciones!D9 -> 12 | H18: Año 3
C19: Total Anual Viatico y refrigerios | F19: =+F18*F17*F16*E7 -> 0 | H19: Precio al publico | I19: =+Mercado!E20 -> 0 | J19: =+I19*$I$8 -> 0 | K19: =IF($E$7="","",$K$6*I19) | L19: =IF($K$6="",J19,+K19+J19) -> 0
H20: Precio x mayor | I20: =+Mercado!D20 -> 80000 | J20: =+$I$8*I20 -> 3200 | K20: =IF($E$7="","",$K$7*I20) | L20: =IF($K$7="",J20,+K20+J20) -> 3200
C21: Total Sueldo comercial | F21: =F19+F13+F11+F9 -> 0 | H21: Precio Promedio Ponderado (PPP) | I21: =+Mercado!F20 -> 80000 | L21: =+Mercado!$J$6*L19+Mercado!$I$6*L20 -> 3200
L22: =+L21/I21 -> 0.04
C23: Consumo energetico area comercial | H23: Año 4
C24: Horas laborables diarias | D24: =+Consideraciones!D12 -> 8 | H24: Precio al publico | I24: =+Mercado!E21 -> 0 | J24: =+I24*$I$8 -> 0 | K24: =IF($E$7="","",$K$6*I24) | L24: =IF($K$6="",J24,+K24+J24) -> 0
C25: Cantidad de locales comerciales | D25: KW por local | E25: Costo KWHR | F25: Total | H25: Precio x mayor | I25: =+Mercado!D21 -> 80000 | J25: =+$I$8*I25 -> 3200 | K25: =IF($E$7="","",$K$7*I25) | L25: =IF($K$7="",J25,+K25+J25) -> 3200
C26: 2 | D26: 0.4 | E26: 8.9 | F26: =C26*D26*E26*Consideraciones!D8*Consideraciones!D12 -> 1253.12 | H26: Precio Promedio Ponderado (PPP) | I26: =+Mercado!F21 -> 80000 | L26: =+Mercado!$J$6*L24+Mercado!$I$6*L25 -> 3200
C27: Consumo de Energia Total Anual: | F27: =F26 -> 1253.12 | L27: =+L26/I26 -> 0.04
H28: Año 5
C29: Puesto | D29: Sueldo Mensual | E29: Cantidad de personal | F29: Total | H29: Precio al publico | I29: =+Mercado!E22 -> 0 | J29: =+I29*$I$8 -> 0 | K29: =IF($E$7="","",$K$6*I29) | L29: =IF($K$6="",J29,+K29+J29) -> 0
C30: Chofer de reparto | F30: =E30*D30 -> 0 | H30: Precio x mayor | I30: =+Mercado!D22 -> 80000 | J30: =+$I$8*I30 -> 3200 | K30: =IF($E$7="","",$K$7*I30) | L30: =IF($K$7="",J30,+K30+J30) -> 3200
C31: Total Sueldo Transporte | F31: =F30*12 -> 0 | H31: Precio Promedio Ponderado (PPP) | I31: =+Mercado!F22 -> 80000 | L31: =+Mercado!$J$6*L29+Mercado!$I$6*L30 -> 3200
L32: =+L31/I31 -> 0.04
C33: Total Aguinaldo Anual | F33: =F30 -> 0
H34: Otros Gastos Comerciales
C35: Total de cargas sociales del empleador | F35: =Consideraciones!D17*(F33+F31) -> 0 | H35: Detalle | K35: Costo
H36: Papelería | K36: 0
C37: Calculo de Viaticos y refrigerio: | H37: Publicidad | K37: 50000
C38: Costo Viatico y refrigerio x persona y día | H38: Seguridad | K38: 0
C39: Días por mes | F39: =+Consideraciones!D8 -> 22 | H39: Mantenimiento | K39: 0
C40: Meses por año | F40: =+Consideraciones!D9 -> 12 | H40: Otros Gastos Comerciales | K40: =SUM(K36:K39) -> 50000
C41: Total Anual Viatico y refrigerios | F41: =+F40*F39*F38 -> 0
C43: Gasto de Combustible y Mantenimiento Annual | H43: Gastos Comercialización Fijos | K43: =K40+F45+F27+F21 -> 51253.12
C45: Total transporte | F45: =F43+F41+F35+F33+F31 -> 0

Sheet Gastos Adm y Finanzas
C3: Gastos Administrativos Fijos
C5: Puesto | D5: Sueldo Mesual Bruto | E5: Cantidad de personal | F5: Total
C6: Contador | D6: 800000 | E6: 1 | F6: =E6*D6 -> 800000
F7: =E7*D7 -> 0
F8: =E8*D8 -> 0
F9: =E9*D9 -> 0
F10: =E10*D10 -> 0
F11: =E11*D11 -> 0
C12: Total Mensual | E12: =SUM(E6:E11) -> 1 | F12: =SUM(F6:F11) -> 800000
C13: Total Sueldo Adm. Anual | F13: =F12*12 -> 9600000
C15: Total Aguinaldo Anual | F15: 0
C17: Total de cargas sociales del empleador | F17: 0
C19: Calculo de Viaticos y refrigerio:
C20: Costo Viatico y refrigerio x persona y día | F20: 0
C21: Días por mes | F21: =+Consideraciones!D8 -> 22
C22: Meses por año | F22: =+Consideraciones!D9 -> 12
C23: Total Anual Viatico y refrigerios | F23: =+F22*F21*F20*E12 -> 0
C25: Total Sueldo administrativo | F25: =F23+F17+F15+F13 -> 9600000
C27: Otros gastos administrativos | F27: 0
C29: Gastos Administrativos Fijos | F29: =+F27+F25 -> 9600000

Sheet Amortización Edificio
C3: Amortización Edificio
C5: Valor inicial | D5: 0 | F5: Vida Util : 33 Años
C6: Valor Final | D6: =+D5-D7 -> 0 | F6: Suma Cuotas | G6: =(COUNT(C10:C42)*(COUNT(C10:C42)+1))/2 -> 561
C7: Valor amortizable | D7: 0
C9: Cuota Número | D9: Valor Amortizable | E9: Amortización Creciente | F9: Valor Cuota | G9: Valor Residual por Cuota
C10: 1 | D10: =+$D$7 -> 0 | E10: =C10/$G$6 -> 0.0017825312 | F10: =D10*E10 -> 0 | G10: =D5-F10 -> 0
C11: =C10+1 -> 2 | D11: =+$D$7 -> 0 | E11: =C11/$G$6 -> 0.0035650624 | F11: =D11*E11 -> 0 | G11: =G10-F11 -> 0
C12: =C11+1 -> 3 | D12: =+$D$7 -> 0 | E12: =C12/$G$6 -> 0.0053475936 | F12: =D12*E12 -> 0 | G12: =G11-F12 -> 0
C13: =C12+1 -> 4 | D13: =+$D$7 -> 0 | E13: =C13/$G$6 -> 0.0071301248 | F13: =D13*E13 -> 0 | G13: =G12-F13 -> 0
C14: =C13+1 -> 5 | D14: =+$D$7 -> 0 | E14: =C14/$G$6 -> 0.008912656 | F14: =D14*E14 -> 0 | G14: =G13-F14 -> 0
C15: =C14+1 -> 6 | D15: =+$D$7 -> 0 | E15: =C15/$G$6 -> 0.010695187 | F15: =D15*E15 -> 0 | G15: =G14-F15 -> 0
C16: =C15+1 -> 7 | D16: =+$D$7 -> 0 | E16: =C16/$G$6 -> 0.012477718 | F16: =D16*E16 -> 0 | G16: =G15-F16 -> 0
C17: =C16+1 -> 8 | D17: =+$D$7 -> 0 | E17: =C17/$G$6 -> 0.01426025 | F17: =D17*E17 -> 0 | G17: =G16-F17 -> 0
C18: =C17+1 -> 9 | D18: =+$D$7 -> 0 | E18: =C18/$G$6 -> 0.016042781 | F18: =D18*E18 -> 0 | G18: =G17-F18 -> 0
C19: =C18+1 -> 10 | D19: =+$D$7 -> 0 | E19: =C19/$G$6 -> 0.017825312 | F19: =D19*E19 -> 0 | G19: =G18-F19 -> 0
C20: =C19+1 -> 11 | D20: =+$D$7 -> 0 | E20: =C20/$G$6 -> 0.019607843 | F20: =D20*E20 -> 0 | G20: =G19-F20 -> 0
C21: =C20+1 -> 12 | D21: =+$D$7 -> 0 | E21: =C21/$G$6 -> 0.021390374 | F21: =D21*E21 -> 0 | G21: =G20-F21 -> 0
C22: =C21+1 -> 13 | D22: =+$D$7 -> 0 | E22: =C22/$G$6 -> 0.023172906 | F22: =D22*E22 -> 0 | G22: =G21-F22 -> 0
... C42: =C41+1 -> 33 | D42: =+$D$7 -> 0 | E42: =C42/$G$6 -> 0.058823529 | F42: =D42*E42 -> 0 | G42: =G41-F42 -> 0
D43: Valor Amortizable | E43: =SUM(E10:E42) -> 1 | F43: =SUM(F10:F42) -> 0 | G43: =+G42-D6 -> 0

Sheet Amortización Muebles y Utiles
C3: Amortización Muebles y Utiles | I3: Detalle de las muebles y útiles
C5: Valor inicial | D5: =+J16 -> 0 | F5: Vida Util : 5 Años | I5: Tipo de mueble | J5: Valor incial | K5: Valor final
C6: Valor Final | D6: =+K16 -> 0 | F6: Cant de cuotas | G6: =(COUNT(C10:C14)*(COUNT(C10:C14)+1))/2 -> 15
C7: Valor amortizable | D7: =+D5-D6 -> 0 | V7: Creciente
V8: Decreciente
C9: Cuota Número | D9: Valor Amortizable | E9: DEFINIR SISTEMA | F9: Valor Cuota | G9: Valor Residual por Cuota | V9: Lineal
C10: 1 | D10: =$D$7 -> 0 | E10: =IF($E$9="Definir sistema",0,IF($E$9="Lineal",$C$10/5,IF($E$9="Decreciente",C14/$G$6,C10/$G$6))) -> 0 | F10: =D10*E10 -> 0 | G10: =D5-F10 -> 0 | V10: DEFINIR SISTEMA
C11: =C10+1 -> 2 | D11: =+D10 -> 0 | E11: =IF($E$9="Definir sistema",0,IF($E$9="Lineal",$C$10/5,IF($E$9="Decreciente",C13/$G$6,C11/$G$6))) -> 0 | F11: =D11*E11 -> 0 | G11: =D5-F10-F11 -> 0
C12: =C11+1 -> 3 | D12: =+D11 -> 0 | E12: =IF($E$9="Definir sistema",0,IF($E$9="Lineal",$C$10/5,IF($E$9="Decreciente",C12/$G$6,C12/$G$6))) -> 0 | F12: =D12*E12 -> 0 | G12: =D5-F10-F11-F12 -> 0
C13: =C12+1 -> 4 | D13: =+D12 -> 0 | E13: =IF($E$9="Definir sistema",0,IF($E$9="Lineal",$C$10/5,IF($E$9="Decreciente",C11/$G$6,C13/$G$6))) -> 0 | F13: =D13*E13 -> 0 | G13: =D5-F10-F11-F12-F13 -> 0
C14: =C13+1 -> 5 | D14: =+D13 -> 0 | E14: =IF($E$9="Definir sistema",0,IF($E$9="Lineal",$C$10/5,IF($E$9="Decreciente",C10/$G$6,C14/$G$6))) -> 0 | F14: =D14*E14 -> 0 | G14: =D5-F10-F11-F12-F13-F14 -> 0
D15: Valor Amortizable | E15: =SUM(E10:E14) -> 0 | F15: =SUM(F10:F14) -> 0 | G15: =+G14-D6 -> 0
J16: =SUM(J6:J15) -> 0 | K16: =SUM(K6:K15) -> 0

Sheet Amortización Rodados
C3: Amortización Rodados | I3: Detalle de los rodados
C5: Valor inicial | D5: =+J16 -> 0 | F5: Vida Util : 5 Años | I5: Tipo de vehiculo | J5: Valor incial | K5: Valor final
C6: Valor Final | D6: =+K16 -> 0 | F6: Suma Cuotas | G6: =(COUNT(C10:C14)*(COUNT(C10:C14)+1))/2 -> 15
C7: Valor amortizable | D7: =+D5-D6 -> 0 | P7: Creciente
P8: Decreciente
C9: Cuota Número | D9: Valor Amortizable | E9: DEFINIR SISTEMA | F9: Valor Cuota | G9: Valor Residual por Cuota | P9: Lineal
C10: 1 | D10: =$D$7 -> 0 | E10: =IF($E$9="Definir sistema",0,IF($E$9="Lineal",$C$10/5,IF($E$9="Decreciente",C14/$G$6,C10/$G$6))) -> 0 | F10: =D10*E10 -> 0 | G10: =D5-F10 -> 0 | P10: DEFINIR SISTEMA
C11: =C10+1 -> 2 | D11: =+D10 -> 0 | E11: =IF($E$9="Definir sistema",0,IF($E$9="Lineal",$C$10/5,IF($E$9="Decreciente",C13/$G$6,C11/$G$6))) -> 0 | F11: =D11*E11 -> 0 | G11: =D5-F10-F11 -> 0
C12: =C11+1 -> 3 | D12: =+D11 -> 0 | E12: =IF($E$9="Definir sistema",0,IF($E$9="Lineal",$C$10/5,IF($E$9="Decreciente",C12/$G$6,C12/$G$6))) -> 0 | F12: =D12*E12 -> 0 | G12: =D5-F10-F11-F12 -> 0
C13: =C12+1 -> 4 | D13: =+D12 -> 0 | E13: =IF($E$9="Definir sistema",0,IF($E$9="Lineal",$C$10/5,IF($E$9="Decreciente",C11/$G$6,C13/$G$6))) -> 0 | F13: =D13*E13 -> 0 | G13: =D5-F10-F11-F12-F13 -> 0
C14: =C13+1 -> 5 | D14: =+D13 -> 0 | E14: =IF($E$9="Definir sistema",0,IF($E$9="Lineal",$C$10/5,IF($E$9="Decreciente",C10/$G$6,C14/$G$6))) -> 0 | F14: =D14*E14 -> 0 | G14: =D5-F10-F11-F12-F13-F14 -> 0
D15: Valor Amortizable | E15: =SUM(E10:E14) -> 0 | F15: =SUM(F10:F14) -> 0 | G15: =+G14-D6 -> 0
J16: =SUM(J6:J15) -> 0 | K16: =SUM(K6:K15) -> 0

Sheet Amortización Informática
C3: Amortización Informática | I3: Detalle de los equipos informáticos
C5: Valor inicial | D5: =+J16 -> 0 | F5: Vida Util : 3 Años | I5: Tipo de máquina | J5: Valor incial | K5: Valor final | R5: Creciente
C6: Valor Final | D6: =+K16 -> 0 | F6: Suma Cuotas | G6: =(COUNT(C10:C12)*(COUNT(C10:C12)+1))/2 -> 6 | R6: Decreciente
C7: Valor amortizable | D7: =+D5-D6 -> 0 | R7: Lineal
R8: DEFINIR SISTEMA
C9: Cuota Número | D9: Valor Amortizable | E9: DEFINIR SISTEMA | F9: Valor Cuota | G9: Valor Residual por Cuota
C10: 1 | D10: =$D$7 -> 0 | E10: =IF($E$9="Definir sistema",0,IF($E$9="Lineal",$C$10/3,IF($E$9="Decreciente",C12/$G$6,C10/$G$6))) -> 0 | F10: =D10*E10 -> 0 | G10: =+D5-F10 -> 0
C11: 2 | D11: =$D$7 -> 0 | E11: =IF($E$9="Definir sistema",0,IF($E$9="Lineal",$C$10/3,IF($E$9="Decreciente",C11/$G$6,C11/$G$6))) -> 0 | F11: =D11*E11 -> 0 | G11: =+G10-F11 -> 0
C12: 3 | D12: =$D$7 -> 0 | E12: =IF($E$9="Definir sistema",0,IF($E$9="Lineal",$C$10/3,IF($E$9="Decreciente",C10/$G$6,C12/$G$6))) -> 0 | F12: =D12*E12 -> 0 | G12: =+G11-F12 -> 0
D13: Valor Amortizable | E13: =SUM(E10:E12) -> 0 | F13: =SUM(F10:F12) -> 0 | G13: =+G12-D6 -> 0
J16: =SUM(J6:J15) -> 0 | K16: =SUM(K6:K15) -> 0

Sheet Amortización Máquinas
C3: Amortización Máquinas | I3: Detalle de las máquinarias
C5: Valor inicial | D5: =+K16 -> 300000 | F5: Vida Util : 5 Años | I5: Cantidad | J5: Tipo de máquina | K5: Valor incial | L5: Valor Final
C6: Valor Final | D6: =+L16 -> 150000 | F6: Suma Cuotas | G6: =(COUNT(C10:C14)*(COUNT(C10:C14)+1))/2 -> 15 | I6: 5 | J6: Costurera | K6: 300000 | L6: 150000 | S6: Creciente
C7: Valor amortizable | D7: =+D5-D6 -> 150000 | S7: Decreciente
S8: Lineal
C9: Cuota Número | D9: Valor Amortizable | E9: Creciente | F9: Valor Cuota | G9: Valor Residual por Cuota | S9: DEFINIR SISTEMA
C10: 1 | D10: =$D$7 -> 150000 | E10: =IF($E$9="Definir sistema",0,IF($E$9="Lineal",$C$10/5,IF($E$9="Decreciente",C14/$G$6,C10/$G$6))) -> 0.066666667 | F10: =D10*E10 -> 10000 | G10: =D5-F10 -> 290000
C11: 2 | D11: =$D$7 -> 150000 | E11: =IF($E$9="Definir sistema",0,IF($E$9="Lineal",$C$10/5,IF($E$9="Decreciente",C13/$G$6,C11/$G$6))) -> 0.13333333 | F11: =D11*E11 -> 20000 | G11: =G10-F11 -> 270000
C12: 3 | D12: =$D$7 -> 150000 | E12: =IF($E$9="Definir sistema",0,IF($E$9="Lineal",$C$10/5,IF($E$9="Decreciente",C12/$G$6,C12/$G$6))) -> 0.2 | F12: =D12*E12 -> 30000 | G12: =G11-F12 -> 240000
C13: 4 | D13: =$D$7 -> 150000 | E13: =IF($E$9="Definir sistema",0,IF($E$9="Lineal",$C$10/5,IF($E$9="Decreciente",C11/$G$6,C13/$G$6))) -> 0.26666667 | F13: =D13*E13 -> 40000 | G13: =G12-F13 -> 200000
C14: 5 | D14: =$D$7 -> 150000 | E14: =IF($E$9="Definir sistema",0,IF($E$9="Lineal",$C$10/5,IF($E$9="Decreciente",C10/$G$6,C14/$G$6))) -> 0.33333333 | F14: =D14*E14 -> 50000 | G14: =G13-F14 -> 150000
D15: Valor Amortizable | E15: =SUM(E10:E14) -> 1 | F15: =SUM(F10:F14) -> 150000 | G15: =+G14-D6 -> 0
K16: =SUM(K6:K15) -> 300000 | L16: =SUM(L6:L15) -> 150000
J17: 0
C21: =+IF((-J17-'Gastos Fijos de Fabricación'!I8-'Gastos Fijos de Fabricación'!I9=0),"","La cantidad de Máquinas difiere en"&" "&(-I17)&" unidades de la cantidad declarada en la hoja Gastos Fijos de Fabricación") -> La cantidad de Máquinas difiere en 0 unidades de la cantidad declarada en la hoja Gastos Fijos de Fabricación

Sheet Activo no Corriente
C3: Activo no Corriente o Activo Fijo
C5: Valores Inciales y Residuales
E7: Año 0 | F7: Año 1 | G7: Año 2 | H7: Año 3 | I7: Año 4 | J7: Año 5
D8: Edificio | E8: =+'Amortización Edificio'!D5 -> 0 | F8: =+'Amortización Edificio'!G10 -> 0 | G8: =+'Amortización Edificio'!G11 -> 0 | H8: =+'Amortización Edificio'!G12 -> 0 | I8: =+'Amortización Edificio'!G13 -> 0 | J8: =+'Amortización Edificio'!G14 -> 0
D9: Muebles y utiles | E9: =+'Amortización Muebles y Utiles'!D5 -> 0 | F9: =+'Amortización Muebles y Utiles'!G10 -> 0 | G9: =+'Amortización Muebles y Utiles'!G11 -> 0 | H9: =+'Amortización Muebles y Utiles'!G12 -> 0 | I9: =+'Amortización Muebles y Utiles'!G13 -> 0 | J9: =+'Amortización Muebles y Utiles'!G14 -> 0
D10: Rodados | E10: =+'Amortización Rodados'!D5 -> 0 | F10: =+'Amortización Rodados'!G10 -> 0 | G10: =+'Amortización Rodados'!G11 -> 0 | H10: =+'Amortización Rodados'!G12 -> 0 | I10: =+'Amortización Rodados'!G13 -> 0 | J10: =+'Amortización Rodados'!G14 -> 0
D11: Informática | E11: 0 | F11: 0 | G11: =+'Amortización Informática'!G11 -> 0 | H11: =+'Amortización Informática'!G12 -> 0 | I11: 0 | J11: 0
D12: Máquinas | E12: =+'Amortización Máquinas'!D5 -> 300000 | F12: =+'Amortización Máquinas'!G10 -> 290000 | G12: =+'Amortización Máquinas'!G11 -> 270000 | H12: =+'Amortización Máquinas'!G12 -> 240000 | I12: =+'Amortización Máquinas'!G13 -> 200000 | J12: =+'Amortización Máquinas'!G14 -> 150000
D13: Inversión Activo Fijo | E13: =SUM(E8:E12) -> 300000 | F13: =SUM(F8:F12) -> 290000 | G13: =SUM(G8:G12) -> 270000 | H13: =SUM(H8:H12) -> 240000 | I13: =SUM(I8:I12) -> 200000 | J13: =SUM(J8:J12) -> 150000
D14: IVA Crédito Fiscal | E14: =+E13*Consideraciones!D15 -> 63000
C16: Cuotas
E18: Año 0 | F18: Año 1 | G18: Año 2 | H18: Año 3 | I18: Año 4 | J18: Año 5
D19: Edificio | E19: 0 | F19: =+'Amortización Edificio'!F10 -> 0 | G19: =+'Amortización Edificio'!F11 -> 0 | H19: =+'Amortización Edificio'!F12 -> 0 | I19: =+'Amortización Edificio'!F13 -> 0 | J19: =+'Amortización Edificio'!F14 -> 0
D20: Muebles y utiles | E20: 0 | F20: =+'Amortización Muebles y Utiles'!F10 -> 0 | G20: =+'Amortización Muebles y Utiles'!F11 -> 0 | H20: =+'Amortización Muebles y Utiles'!F12 -> 0 | I20: =+'Amortización Muebles y Utiles'!F13 -> 0 | J20: =+'Amortización Muebles y Utiles'!F14 -> 0
D21: Rodados | E21: 0 | F21: =+'Amortización Rodados'!F10 -> 0 | G21: =+'Amortización Rodados'!F11 -> 0 | H21: =+'Amortización Rodados'!F12 -> 0 | I21: =+'Amortización Rodados'!F13 -> 0 | J21: =+'Amortización Rodados'!F14 -> 0
D22: Informática | E22: 0 | F22: =+'Amortización Informática'!F10 -> 0 | G22: =+'Amortización Informática'!F11 -> 0 | H22: =+'Amortización Informática'!F12 -> 0 | I22: 0 | J22: 0
D23: Máquinas | E23: 0 | F23: =+'Amortización Máquinas'!F10 -> 10000 | G23: =+'Amortización Máquinas'!F11 -> 20000 | H23: =+'Amortización Máquinas'!F12 -> 30000 | I23: =+'Amortización Máquinas'!F13 -> 40000 | J23: =+'Amortización Máquinas'!F14 -> 50000
D24: AMORTIZACIÓN | E24: 0 | F24: =SUM(F19:F23) -> 10000 | G24: =SUM(G19:G23) -> 20000 | H24: =SUM(H19:H23) -> 30000 | I24: =SUM(I19:I23) -> 40000 | J24: =SUM(J19:J23) -> 50000

Sheet Capital de trabajo
C2: Inversiones en Capital de Trabajo
C4: Disponibilidades mínimas en caja y Bancos | D4: =+('Costos Variables de Fabricación'!F17+'Gastos de Comercialización'!F21+'Gastos Adm y Finanzas'!F17)/12*3 -> 7800000 | E4: Sueldo de tres meses
C5: Stock de Materias primas | D5: =+'Costos Variables de Fabricación'!L23/60*3 -> 5814000 | E5: Materia Prima por 3 meses
C7: Iva Activo de Trabajo | D7: =+D5*21% -> 1220940
C9: Total Activo de Trabajo sin IVA | D9: =+D4+D5 -> 13614000
C12: Activo de Trabajo | D12: Año 0 | E12: Año 1 | F12: Año 2 | G12: Año 3 | H12: Año 4 | I12: Año 5
C13: Disponibilidades mínimas caja y bancos | D13: =+D9 -> 13614000 | E13: =+'Balances Pro Forma'!F30 -> 13968523 | F13: =+'Balances Pro Forma'!I30 -> 15091042 | G13: =+'Balances Pro Forma'!L30 -> 18594131 | H13: =+'Balances Pro Forma'!O30 -> -6832128.3 | I13: =+'Balances Pro Forma'!R30 -> 38310123
C14: Crédito x ventas | D14: 0 | E14: =+'Balances Pro Forma'!F32 -> 0 | F14: =+'Balances Pro Forma'!I32 -> 0 | G14: =+'Balances Pro Forma'!L32 -> 0 | H14: =+'Balances Pro Forma'!O32 -> 0 | I14: =+'Balances Pro Forma'!R32 -> 0
C15: Bienes de Cambio | D15: 0 | E15: =+'Balances Pro Forma'!F34 -> 0 | F15: =+'Balances Pro Forma'!I34 -> 0 | G15: =+'Balances Pro Forma'!L34 -> 0 | H15: =+'Balances Pro Forma'!O34 -> 32476932 | I15: =+'Balances Pro Forma'!R34 -> 0
C16: Activo Corriente | D16: =SUM(D13:D15) -> 13614000 | E16: =SUM(E13:E15) -> 13968523 | F16: =SUM(F13:F15) -> 15091042 | G16: =SUM(G13:G15) -> 18594131 | H16: =SUM(H13:H15) -> 25644803 | I16: =SUM(I13:I15) -> 38310123
C17: Deudas con proveedores | D17: 0 | E17: =+'Balances Pro Forma'!F46 -> 0 | F17: =+'Balances Pro Forma'!I46 -> 0 | G17: =+'Balances Pro Forma'!L46 -> 0 | H17: =+'Balances Pro Forma'!O46 -> 0 | I17: =+'Balances Pro Forma'!R46 -> 0
C18: Deudas bancarias corto plazo | D18: 0 | E18: 0 | F18: 0 | G18: 0 | H18: 0 | I18: 0
C19: Deudas Impositivas | D19: 0 | E19: 0 | F19: 0 | G19: 0 | H19: 0 | I19: 0
C20: Pasivo Corriente | D20: =SUM(D17:D19) -> 0 | E20: =SUM(E17:E19) -> 0 | F20: =SUM(F17:F19) -> 0 | G20: =SUM(G17:G19) -> 0 | H20: =SUM(H17:H19) -> 0 | I20: =SUM(I17:I19) -> 0
C21: Capital de Trabajo | D21: =+D16-D20 -> 13614000 | E21: =+E16-E20 -> 13968523 | F21: =+F16-F20 -> 15091042 | G21: =+G16-G20 -> 18594131 | H21: =+H16-H20 -> 25644803 | I21: =+I16-I20 -> 38310123
C22: Variación | E22: =+E21-D21 -> 354523.41 | F22: =+F21-E21 -> 1122518.8 | G22: =+G21-F21 -> 3503089.1 | H22: =+H21-G21 -> 7050671.9 | I22: =+I21-H21 -> 12665320

Sheet Flujo de caja
C3: Flujo de Caja
C5: TIR Pura
C6: Año | D6: Inversion en Activo Fijo | E6: Inversion en activo de trabajo | F6: Credito Fiscal | G6: Impuesto a las ganancias | H6: Honorarios | I6: Total de Egresos | J6: Utilidades antes de I&H&I | K6: Amortizacion del Capital Fijo | L6: Recuperacion de Credito Fiscal | M6: Total de Ingresos | N6: Ingesos menos Egresos | O6: Ingresos menos Egresos Acumulados | P6: Aux
C7: 0 | D7: ='Activo no Corriente'!E13 -> 300000 | E7: =+'Capital de trabajo'!D13 -> 13614000 | F7: =+'Activo no Corriente'!E14+'Capital de trabajo'!D7 -> 1283940 | G7: 0 | H7: 0 | I7: =SUM(D7:H7) -> 15197940 | J7: 0 | K7: 0 | L7: 0 | M7: 0 | N7: =+M7-I7 -> -15197940 | O7: =N7 -> -15197940
C8: 1 | D8: 0 | E8: 0 | F8: 0 | G8: =-'Balances Pro Forma'!F24 -> 154109.86 | H8: 0 | I8: =SUM(D8:H8) -> 154109.86 | J8: =+'Balances Pro Forma'!F15 -> 2789386.9 | K8: =-'Balances Pro Forma'!F17 -> 10000 | L8: =F7 -> 1283940 | M8: =SUM(J8:L8) -> 4083326.9 | N8: =+M8-I8 -> 3929217 | O8: =SUM(N7:N8) -> -11268723 | P8: =+IF(AND(O7<0,O8<0),0,IF(AND(O7<0,O8>0),O8*12/(-O7+O8),"")) -> 0
C9: 2 | D9: 0 | E9: 0 | F9: 0 | G9: =-'Balances Pro Forma'!I24 -> 3009345 | H9: 0 | I9: =SUM(D9:H9) -> 3009345 | J9: =+'Balances Pro Forma'!I15 -> 10489387 | K9: =-'Balances Pro Forma'!I17 -> 20000 | L9: 0 | M9: =SUM(J9:L9) -> 10509387 | N9: =+M9-I9 -> 7500041.9 | O9: =SUM(N7:N9) -> -3768681.1 | P9: =+IF(AND(O8<0,O9<0),0,IF(AND(O8<0,O9>0),-O8*12/(-O8+O9),"")) -> 0
C10: 3 | D10: 0 | E10: 0 | F10: 0 | G10: =-'Balances Pro Forma'!L24 -> 6942580.1 | H10: 0 | I10: =SUM(D10:H10) -> 6942580.1 | J10: =+'Balances Pro Forma'!L15 -> 21269387 | K10: =-'Balances Pro Forma'!L17 -> 30000 | L10: 0 | M10: =SUM(J10:L10) -> 21299387 | N10: =+M10-I10 -> 14356807 | O10: =SUM(N7:N10) -> 10588126 | P10: =+IF(AND(O9<0,O10<0),0,IF(AND(O9<0,O10>0),-O9*12/(-O9+O10),"")) -> 3.1500161
C11: 4 | D11: 0 | E11: 0 | F11: 0 | G11: =-'Balances Pro Forma'!O24 -> 12385015 | H11: 0 | I11: =SUM(D11:H11) -> 12385015 | J11: =+'Balances Pro Forma'!O15 -> 36361387 | K11: =-'Balances Pro Forma'!O17 -> 40000 | L11: 0 | M11: =SUM(J11:L11) -> 36401387 | N11: =+M11-I11 -> 24016372 | O11: =SUM(N7:N11) -> 34604497 | P11: =+IF(AND(O10<0,O11<0),0,IF(AND(O10<0,O11>0),-O10*12/(-O10+O11),""))
C12: 5 | D12: =-'Activo no Corriente'!J13 -> -150000 | E12: =-E7 -> -13614000 | F12: 0 | G12: =-'Balances Pro Forma'!R24 -> 21007550 | H12: 0 | I12: =SUM(D12:H12) -> 7243550.3 | J12: =+'Balances Pro Forma'!R15 -> 60539387 | K12: =-'Balances Pro Forma'!R17 -> 50000 | L12: 0 | M12: =SUM(J12:L12) -> 60589387 | N12: =+M12-I12 -> 53345837 | O12: =SUM(N7:N12) -> 87950334
C13: Total | D13: =SUM(D7:D12) -> 150000 | E13: =SUM(E7:E12) -> 0 | F13: =SUM(F7:F12) -> 1283940 | G13: =SUM(G7:G12) -> 43498600 | H13: =SUM(H7:H12) -> 0 | I13: =SUM(I7:I12) -> 44932540 | J13: =SUM(J7:J12) -> 1.3144893e+08 | K13: =SUM(K7:K12) -> 150000 | ... N13: =SUM(N7:N12) -> 87950334
I14: Impuesto a las ganancias | J14: =-G13 -> -43498600
I15: Beneficio del Proyecto | J15: =J14+J13 -> 87950334
C17: PRP | D17: =COUNTIF(O7:O12,"<0") -> 3 | E17: Años | F17: =ROUNDUP(SUMIFS(P8:P11,P8:P11,">0"),0) -> 4 | G17: Meses
C19: TIR | D19: =IRR(N7:N12,0.1) -> 0.67408847
C21: VAN (0%) | D21: =+O12 -> 87950334
C23: Tasa VAN | D23: =+'Cuadro de Usos y Fuentes'!D15 -> 0.65
C25: =+"VAN"&"("&D23*100&"%"&")" -> VAN(65%) | D25: {=NPV(D23,N8,N9,N10,N11,N12)+N7} -> 736384.27
C28: TIR Modificada
C29: Año | D29: Inversion en Activo Fijo | E29: Inversion en activo de trabajo | F29: Credito Fiscal | G29: Impuesto a las ganancias | H29: Honorarios | I29: Total de Egresos | J29: Utilidades antes de I&H&I | K29: Amortizacion del Capital Fijo | L29: Recuperacion de Credito Fiscal | M29: Total de Ingresos | N29: Intereses Ganados | O29: Intereses Pérdidos | P29: Intereses | Q29: Ingesos menos Egresos | R29: Ingresos menos Egresos Acumulados | S29: Aux
C30: 0 | D30: ='Activo no Corriente'!E13 -> 300000 | E30: =+E7 -> 13614000 | F30: =+'Activo no Corriente'!E14+'Capital de trabajo'!D7 -> 1283940 | G30: 0 | H30: 0 | I30: =SUM(D30:H30) -> 15197940 | J30: 0 | K30: 0 | L30: 0 | M30: 0 | N30: 0 | O30: 0 | P30: =N30-O30 -> 0 | Q30: =+P30+M30-I30 -> -15197940 | R30: =Q30 -> -15197940
C31: 1 | D31: 0 | E31: =+E8 -> 0 | F31: 0 | G31: =-'Balances Pro Forma'!F24 -> 154109.86 | H31: 0 | I31: =SUM(D31:H31) -> 154109.86 | J31: =+'Balances Pro Forma'!F15 -> 2789386.9 | K31: =-'Balances Pro Forma'!F17 -> 10000 | L31: =F30 -> 1283940 | M31: =SUM(J31:L31) -> 4083326.9 | N31: =+'Balances Pro Forma'!F22 -> 0 | O31: =-'Balances Pro Forma'!F21 -> 2339073 | P31: =N31-O31 -> -2339073 | Q31: =+P31+M31-I31 -> 1590144 | R31: =SUM(Q30:Q31) -> -13607796 | S31: =+IF(AND(R30<0,R31<0),0,IF(AND(R30<0,R31>0),R31*12/(-R30+R31),"")) -> 0
C32: 2 | D32: 0 | E32: =+E9 -> 0 | F32: 0 | G32: =-'Balances Pro Forma'!I24 -> 3009345 | H32: 0 | I32: =SUM(D32:H32) -> 3009345 | J32: =+'Balances Pro Forma'!I15 -> 10489387 | K32: =-'Balances Pro Forma'!I17 -> 20000 | L32: 0 | M32: =SUM(J32:L32) -> 10509387 | N32: =+'Balances Pro Forma'!I22 -> 0 | O32: =-'Balances Pro Forma'!I21 -> 1871258.4 | P32: =N32-O32 -> -1871258.4 | Q32: =+P32+M32-I32 -> 5628783.5 | R32: =SUM(Q30:Q32) -> -7979012.5 | S32: =+IF(AND(R31<0,R32<0),0,IF(AND(R31<0,R32>0),-R31*12/(-R31+R32),"")) -> 0
C33: 3 | D33: 0 | E33: =+E10 -> 0 | F33: 0 | G33: =-'Balances Pro Forma'!L24 -> 6942580.1 | H33: 0 | I33: =SUM(D33:H33) -> 6942580.1 | J33: =+'Balances Pro Forma'!L15 -> 21269387 | K33: =-'Balances Pro Forma'!L17 -> 30000 | L33: 0 | M33: =SUM(J33:L33) -> 21299387 | N33: =+'Balances Pro Forma'!L22 -> 0 | O33: =-'Balances Pro Forma'!L21 -> 1403443.8 | P33: =N33-O33 -> -1403443.8 | Q33: =+P33+M33-I33 -> 12953363 | R33: =SUM(Q30:Q33) -> 4974350.5 | S33: =+IF(AND(R32<0,R33<0),0,IF(AND(R32<0,R33>0),-R32*12/(-R32+R33),"")) -> 7.3917599
C34: 4 | D34: 0 | E34: =+E11 -> 0 | F34: 0 | G34: =-'Balances Pro Forma'!O24 -> 12385015 | H34: 0 | I34: =SUM(D34:H34) -> 12385015 | J34: =+'Balances Pro Forma'!O15 -> 36361387 | K34: =-'Balances Pro Forma'!O17 -> 40000 | L34: 0 | M34: =SUM(J34:L34) -> 36401387 | N34: =+'Balances Pro Forma'!O22 -> 0 | O34: =-'Balances Pro Forma'!O21 -> 935629.2 | P34: =N34-O34 -> -935629.2 | Q34: =+P34+M34-I34 -> 23080742 | R34: =SUM(Q30:Q34) -> 28055093 | S34: =+IF(AND(R33<0,R34<0),0,IF(AND(R33<0,R34>0),-R33*12/(-R33+R34),""))
C35: 5 | D35: =-'Activo no Corriente'!J13 -> -150000 | E35: =-E30 -> -13614000 | F35: 0 | G35: =-'Balances Pro Forma'!R24 -> 21007550 | H35: 0 | I35: =SUM(D35:H35) -> 7243550.3 | J35: =+'Balances Pro Forma'!R15 -> 60539387 | K35: =-'Balances Pro Forma'!R17 -> 50000 | L35: 0 | M35: =SUM(J35:L35) -> 60589387 | N35: =+'Balances Pro Forma'!R22 -> 0 | O35: =-'Balances Pro Forma'!R21 -> 467814.6 | P35: =N35-O35 -> -467814.6 | Q35: =+P35+M35-I35 -> 52878022 | R35: =SUM(Q30:Q35) -> 80933115
C36: Total | D36: =SUM(D30:D35) -> 150000 | E36: =SUM(E30:E35) -> 0 | F36: =SUM(F30:F35) -> 1283940 | G36: =SUM(G30:G35) -> 43498600 | H36: =SUM(H30:H35) -> 0 | I36: =SUM(I30:I35) -> 44932540 | J36: =SUM(J30:J35) -> 1.3144893e+08 | K36: =SUM(K30:K35) -> 150000 | ... Q36: =SUM(Q30:Q35) -> 80933115
I37: Impuesto a las ganancias | J37: =-G36 -> -43498600
I38: Intereses | J38: =+P36 -> -7017219
I39: Beneficio del proyecto | J39: =J38+J37+J36 -> 80933115
C41: PRP | D41: =COUNTIF(R30:R35,"<0") -> 3 | E41: Años | F41: =ROUNDUP(SUMIFS(S31:S34,S31:S34,">0"),0) -> 8 | G41: Meses
C43: TIR modificada | D43: =IRR(Q30:Q35,0.1) -> 0.59188895
C45: VAN (0%) | D45: =+Q36 -> 80933115
C47: Tasa VAN | D47: =+D23 -> 0.65
C49: =+"VAN"&"("&D47*100&"%"&")" -> VAN(65%) | D49: {=NPV(D47,Q31,Q32,Q33,Q34,Q35)+Q30} -> -1845473.3

Sheet Cuadro de Usos y Fuentes
C3: Fuentes y Usos
C5: USOS | D5: Importe | E5: FUENTES | F5: Importe | G5: Indice Endeudamiento
C6: Activo de Trabajo | D6: =+'Capital de trabajo'!D21 -> 13614000 | E6: Préstamo | F6: =IF(F7<D10,D10-F7,0) -> 5197940 | G6: =F6/F10 -> 0.34201609
C7: Activo no Corriente | D7: ='Activo no Corriente'!E13 -> 300000 | E7: Capital Social | F7: 10000000 | G7: =F7/F10 -> 0.65798391
C8: Crédito Fiscal | D8: ='Activo no Corriente'!E14+'Capital de trabajo'!D7 -> 1283940
C10: Total Usos | D10: =+SUM(D6:D8) -> 15197940 | E10: Fuentes | F10: =SUM(F6:F9) -> 15197940 | G10: =G7+G6 -> 1
C12: Tasa Bancaria | D12: =+Consideraciones!D5 -> 0.45 | E12: Ponderación | F12: Tasa de impuesto a las ganancias | G12: =+Consideraciones!D16 -> 0.35
E13: =D12*G6 -> 0.15390724
C15: Tasa de dividendos de los socios | D15: =+Consideraciones!D6 -> 0.65
C17: WACC = | D17: =E13*(1-G12) -> 0.10003971
C18: Tasa Nominal Anual | D18: =+D12 -> 0.45 | E18: Meses = | F18: 12
C19: Tasa Efectiva Anual | D19: =INT.EFECTIVO(D18,F18) -> #NAME?

Sheet Balances Pro Forma
C3: Estado de Resultados Proyectados y Balance Proforma
C5: Estado de Resultados Proyectados
D6: Unidades | E6: $ unitario | F6: Total Año 1 | G6: Unidades | H6: $ unitario | I6: Total Año 2 | J6: Unidades | K6: $ unitario | L6: Total Año 3 | M6: Unidades | N6: $ unitario | O6: Total Año 4 | P6: Unidades | Q6: $ unitario | R6: Total Año 5
C7: Ingresos por ventas | D7: =+Mercado!H18 -> 900 | E7: =+Mercado!F18 -> 80000 | F7: =D7*E7 -> 72000000 | G7: =+Mercado!H19 -> 1260 | H7: =+Mercado!F19 -> 80000 | I7: =G7*H7 -> 100800000 | J7: =+Mercado!H20 -> 1764 | K7: =+Mercado!F20 -> 80000 | L7: =J7*K7 -> 141120000 | M7: =+Mercado!H21 -> 2469.6 | N7: =+Mercado!F21 -> 80000 | O7: =M7*N7 -> 197568000 | P7: =+Mercado!H22 -> 3600 | Q7: =+Mercado!F22 -> 80000 | R7: =P7*Q7 -> 288000000
C8: Costo de ventas | D8: =+D7 -> 900 | E8: =+'Costos Variables de Fabricación'!L27*E7 -> 55411.111 | F8: =-D8*E8 -> -49870000 | G8: =+G7 -> 1260 | H8: =+'Costos Variables de Fabricación'!L27*H7 -> 55411.111 | I8: =-G8*H8 -> -69818000 | J8: =+J7 -> 1764 | K8: =+'Costos Variables de Fabricación'!L27*K7 -> 55411.111 | L8: =-J8*K8 -> -97745200 | M8: =+M7 -> 2469.6 | N8: =+'Costos Variables de Fabricación'!L27*N7 -> 55411.111 | O8: =-M8*N8 -> -136843280 | P8: =+P7 -> 3600 | Q8: =+'Costos Variables de Fabricación'!L27*Q7 -> 55411.111 | R8: =-P8*Q8 -> -199480000
C9: Costos variables comercialización | D9: =+D7 -> 900 | E9: =+'Gastos de Comercialización'!L12*E7 -> 3200 | F9: =-D9*E9 -> -2880000 | G9: =+G7 -> 1260 | H9: =+'Gastos de Comercialización'!L17*H7 -> 3200 | I9: =-G9*H9 -> -4032000 | J9: =+J7 -> 1764 | K9: =+'Gastos de Comercialización'!L22*K7 -> 3200 | L9: =-J9*K9 -> -5644800 | M9: =+M7 -> 2469.6 | N9: =+'Gastos de Comercialización'!L27*N7 -> 3200 | O9: =-M9*N9 -> -7902720 | P9: =+P7 -> 3600 | Q9: =+'Gastos de Comercialización'!L32*Q7 -> 3200 | R9: =-P9*Q9 -> -11520000
C10: Contribución Marginal | F10: =SUM(F7:F9) -> 19250000 | I10: =SUM(I7:I9) -> 26950000 | L10: =SUM(L7:L9) -> 37730000 | O10: =SUM(O7:O9) -> 52822000 | R10: =SUM(R7:R9) -> 77000000
C12: Gastos de fabricación (fijos) | F12: =-'Gastos Fijos de Fabricación'!L27 -> -6809360 | I12: =-'Gastos Fijos de Fabricación'!L27 -> -6809360 | L12: =-'Gastos Fijos de Fabricación'!L27 -> -6809360 | O12: =-'Gastos Fijos de Fabricación'!L27 -> -6809360 | R12: =-'Gastos Fijos de Fabricación'!L27 -> -6809360
C13: Gastos de comercialización (fijos) | F13: =-'Gastos de Comercialización'!K43 -> -51253.12 | I13: =-'Gastos de Comercialización'!K43 -> -51253.12 | L13: =-'Gastos de Comercialización'!K43 -> -51253.12 | O13: =-'Gastos de Comercialización'!K43 -> -51253.12 | R13: =-'Gastos de Comercialización'!K43 -> -51253.12
C14: Gastos administrativos (fijos) | F14: =-'Gastos Adm y Finanzas'!F29 -> -9600000 | I14: =-'Gastos Adm y Finanzas'!F29 -> -9600000 | L14: =-'Gastos Adm y Finanzas'!F29 -> -9600000 | O14: =-'Gastos Adm y Finanzas'!F29 -> -9600000 | R14: =-'Gastos Adm y Finanzas'!F29 -> -9600000
C15: Utilidades antes de amortizaciones, honorarios intereses e impuesto a las ganancias (EBITDA) | F15: =SUM(F10:F14) -> 2789386.9 | I15: =SUM(I10:I14) -> 10489387 | L15: =SUM(L10:L14) -> 21269387 | O15: =SUM(O10:O14) -> 36361387 | R15: =SUM(R10:R14) -> 60539387
C17: Cuota de amortización | F17: =-'Activo no Corriente'!F24 -> -10000 | I17: =-'Activo no Corriente'!G24 -> -20000 | L17: =-'Activo no Corriente'!H24 -> -30000 | O17: =-'Activo no Corriente'!I24 -> -40000 | R17: =-'Activo no Corriente'!J24 -> -50000
C18: Utilidad antes de honorarios, intereses e impuesto a las ganancias | F18: =F15+F17 -> 2779386.9 | I18: =I15+I17 -> 10469387 | L18: =L15+L17 -> 21239387 | O18: =O15+O17 -> 36321387 | R18: =R15+R17 -> 60489387
C19: Honorarios | F19: 0 | I19: 0 | L19: 0 | O19: 0 | R19: 0
C20: Utilidad antes de intereses (BAII o EBIT) | F20: =SUM(F18:F19) -> 2779386.9 | I20: =SUM(I18:I19) -> 10469387 | L20: =SUM(L18:L19) -> 21239387 | O20: =SUM(O18:O19) -> 36321387 | R20: =SUM(R18:R19) -> 60489387
C21: Intereses perdidos | F21: =-F75 -> -2339073 | I21: =-I75 -> -1871258.4 | L21: =-L75 -> -1403443.8 | O21: =-O75 -> -935629.2 | R21: =-R75 -> -467814.6
C22: Intereses ganados | E22: =+'Cuadro de Usos y Fuentes'!D18 -> 0.45 | F22: =+E22*F31 -> 0 | I22: =+E22*I31 -> 0 | L22: =+E22*L31 -> 0 | O22: =+E22*O31 -> 0 | R22: =+E22*R31 -> 0
C23: Resultado antes de impuestos (BAI) | F23: =SUM(F20:F22) -> 440313.88 | I23: =SUM(I20:I22) -> 8598128.5 | L23: =SUM(L20:L22) -> 19835943 | O23: =SUM(O20:O22) -> 35385758 | R23: =SUM(R20:R22) -> 60021572
C24: Impuesto a las ganancias | F24: =-Consideraciones!$D$16*F23 -> -154109.86 | I24: =-Consideraciones!$D$16*I23 -> -3009345 | L24: =-Consideraciones!$D$16*L23 -> -6942580.1 | O24: =-Consideraciones!$D$16*O23 -> -12385015 | R24: =-Consideraciones!$D$16*R23 -> -21007550
C25: Resultado operativo (BN) | F25: =SUM(F23:F24) -> 286204.02 | I25: =SUM(I23:I24) -> 5588783.5 | L25: =SUM(L23:L24) -> 12893363 | O25: =SUM(O23:O24) -> 23000742 | R25: =SUM(R23:R24) -> 39014022
C28: Balance General Pro Forma | F28: =+IF(F34/'Costos Variables de Fabricación'!$L$26>Mercado!$H$18,"La cantidad de dias supera la capacidad máx","") | I28: =+IF(I34/'Costos Variables de Fabricación'!$L$26>Mercado!$H$19,"La cantidad de dias supera la capacidad máx","") | L28: =+IF(L34/'Costos Variables de Fabricación'!$L$26>Mercado!$H$20,"La cantidad de dias supera la capacidad máx","") | O28: =+IF(O34/'Costos Variables de Fabricación'!$L$26>Mercado!$H$21,"La cantidad de dias supera la capacidad máx","") | R28: =+IF(R34/'Costos Variables de Fabricación'!$L$26>Mercado!$H$18,"La cantidad de dias supera la capacidad máx","")
D29: Año 0 | F29: Año 1 | I29: Año 2 | L29: Año 3 | O29: Año 4 | R29: Año 5
C30: Cajas y bancos | D30: =+'Capital de trabajo'!D13 -> 13614000 | E30: =D30/$D$42 -> 0.8957793 | F30: =+D30+F89 -> 13968523 | G30: =F30*365/F7 -> 70.812653 | H30: =F30/$F$42 -> 0.97966129 | I30: =F30+I89 -> 15091042 | J30: =I30*365/I7 -> 54.645143 | K30: =L30/$L$42 -> 0.98725718 | L30: =I30+L89 -> 18594131 | M30: =L30*365/L7 -> 48.092814 | N30: =O30/$O$42 -> -0.26435211 | O30: =L30+O89 -> -6832128.3 | P30: =O30*365/O7 -> -12.622119 | Q30: =R30/$R$42 -> 0.99609986 | R30: =O30+R89 -> 38310123 | S30: =R30*365/R7 -> 48.55276 | T30: días de ventas
C31: Inversiones financieras | D31: 0 | E31: =D31/$D$42 -> 0 | F31: 0 | H31: =F31/$F$42 -> 0 | I31: 0 | K31: =L31/$L$42 -> 0 | L31: 0 | N31: =O31/$O$42 -> 0 | O31: 0 | Q31: =R31/$R$42 -> 0
C32: Cuentas por cobrar | D32: 0 | E32: =D32/$D$42 -> 0 | F32: =G32*F7/365 -> 0 | H32: =F32/$F$42 -> 0 | I32: =J32*I7/365 -> 0 | K32: =L32/$L$42 -> 0 | L32: =M32*L7/365 -> 0 | N32: =O32/$O$42 -> 0 | O32: =P32*O7/365 -> 0 | Q32: =R32/$R$42 -> 0 | R32: =S32*R7/365 -> 0 | T32: días de ventas
C33: Crédito Fiscal IVA | D33: ='Activo no Corriente'!E14+'Capital de trabajo'!D7 -> 1283940 | E33: =D33/$D$42 -> 0.084481186 | F33: 0 | H33: =F33/$F$42 -> 0 | I33: 0 | K33: =L33/$L$42 -> 0 | L33: 0 | N33: =O33/$O$42 -> 0 | O33: 0 | Q33: =R33/$R$42 -> 0 | R33: 0
C34: Inventarios | D34: 0 | E34: =D34/$D$42 -> 0 | F34: =G34*F7/365 -> 0 | H34: =F34/$F$42 -> 0 | I34: =J34*I7/365 -> 0 | K34: =L34/$L$42 -> 0 | L34: =M34*L7/365 -> 0 | N34: =O34/$O$42 -> 1.2566136 | O34: =P34*O7/365 -> 32476932 | P34: 60 | Q34: =R34/$R$42 -> 0 | R34: =S34*R7/365 -> 0 | T34: días de ventas
C35: Activo corriente | D35: =SUM(D30:D34) -> 14897940 | E35: =D35/$D$42 -> 0.98026048 | F35: =SUM(F30:F34) -> 13968523 | H35: =F35/$F$42 -> 0.97966129 | I35: =SUM(I30:I34) -> 15091042 | L35: =SUM(L30:L34) -> 18594131 | O35: =SUM(O30:O34) -> 25644803 | R35: =SUM(R30:R34) -> 38310123
H39: =F39/$F$42 -> 0
C40: Bienes de uso | D40: ='Activo no Corriente'!E13 -> 300000 | E40: =D40/$D$42 -> 0.019739517 | F40: ='Activo no Corriente'!F13 -> 290000 | H40: =F40/$F$42 -> 0.020338712 | I40: ='Activo no Corriente'!G13 -> 270000 | K40: =L40/$L$42 -> 0.012742823 | L40: ='Activo no Corriente'!H13 -> 240000 | N40: =O40/$O$42 -> 0.0077384996 | O40: ='Activo no Corriente'!I13 -> 200000 | Q40: =R40/$R$42 -> 0.0039001435 | R40: ='Activo no Corriente'!J13 -> 150000
C41: Activo No Corriente | D41: =D40 -> 300000 | E41: =D41/$D$42 -> 0.019739517 | F41: =F40 -> 290000 | H41: =F41/$F$42 -> 0.020338712 | I41: =I40 -> 270000 | L41: =L40 -> 240000 | O41: =O40 -> 200000 | R41: =R40 -> 150000
C42: Total Activo | D42: =D41+D35 -> 15197940 | E42: =D42/$D$42 -> 1 | F42: =F41+F35 -> 14258523 | H42: =F42/$F$42 -> 1 | I42: =I41+I35 -> 15361042 | K42: =SUM(K30:K41) -> 1 | L42: =L41+L35 -> 18834131 | N42: =SUM(N30:N41) -> 1 | O42: =O41+O35 -> 25844803 | Q42: =SUM(Q30:Q41) -> 1 | R42: =R41+R35 -> 38460123
C46: Cuentas por pagar | D46: 0 | E46: =D46/$D$62 -> 0 | F46: =G46*F7/365 -> 0 | G46: 0 | H46: =I46/$I$62 -> 0 | I46: =J46*I7/365 -> 0 | J46: 0 | K46: =L46/$L$62 -> 0 | L46: =M46*L7/365 -> 0 | M46: 0 | N46: =O46/$O$62 -> 0 | O46: =P46*O7/365 -> 0 | P46: 0 | Q46: =R46/$R$62 -> 0 | R46: =S46*R7/365 -> 0 | S46: 0 | T46: días de ventas
C47: Impuestos por pagar | D47: 0 | E47: =D47/$D$62 -> 0 | F47: 0 | H47: =I47/$I$62 -> 0 | I47: 0 | K47: =L47/$L$62 -> 0 | L47: 0 | N47: =O47/$O$62 -> 0 | O47: 0 | Q47: =R47/$R$62 -> 0 | R47: 0
C48: Pasivo Corriente | D48: =SUM(D46:D47) -> 0 | E48: =D48/$D$62 -> 0 | F48: =SUM(F46:F47) -> 0 | I48: =SUM(I46:I47) -> 0 | L48: =SUM(L46:L47) -> 0 | O48: =SUM(O46:O47) -> 0 | R48: =SUM(R46:R47) -> 0
C52: Prestamos Bancarios | D52: ='Cuadro de Usos y Fuentes'!F6 -> 5197940 | E52: =D52/$D$62 -> 0.34201609 | F52: =+F74 -> 4158352 | H52: =I52/$I$62 -> 0.20303075 | I52: =+I74 -> 3118764 | K52: =L52/$L$62 -> 0.11039405 | L52: =+L74 -> 2079176 | N52: =O52/$O$62 -> 0.040224257 | O52: =+O74 -> 1039588 | Q52: =R52/$R$62 -> 0 | R52: =+R74 -> 0
C53: Pasivo No Corriente | D53: =SUM(D52) -> 5197940 | E53: =D53/$D$62 -> 0.34201609 | F53: =SUM(F52) -> 4158352 | I53: =SUM(I52) -> 3118764 | L53: =SUM(L52) -> 2079176 | O53: =SUM(O52) -> 1039588 | R53: =SUM(R52) -> 0
C54: Total Pasivo | D54: =D53+D48 -> 5197940 | E54: =D54/$D$62 -> 0.34201609 | F54: =F53+F48 -> 4158352 | I54: =I53+I48 -> 3118764 | L54: =L53+L48 -> 2079176 | O54: =O53+O48 -> 1039588 | R54: =R53+R48 -> 0
C58: Capital | D58: ='Cuadro de Usos y Fuentes'!F7 -> 10000000 | E58: =D58/$D$62 -> 0.65798391 | F58: =D58 -> 10000000 | H58: =I58/$I$62 -> 0.65099749 | I58: =D58 -> 10000000 | K58: =L58/$L$62 -> 0.53095095 | L58: =D58 -> 10000000 | N58: =O58/$O$62 -> 0.38692498 | O58: =D58 -> 10000000 | Q58: =R58/$R$62 -> 0.26000957 | R58: =D58 -> 10000000
C59: Resultados no asignados | D59: 0 | E59: =D59/$D$62 -> 0 | F59: =-F67 -> -186032.61 | H59: =I59/$I$62 -> -0.21785665 | I59: =+F60-I67 -> -3346505.3 | K59: =L59/$L$62 -> -0.32591934 | L59: =+I59+I60-L67 -> -6138407.7 | N59: =O59/$O$62 -> -0.31710543 | O59: =+L59+L60-O67 -> -8195527.3 | Q59: =R59/$R$62 -> -0.27441148 | R59: =+O59+O60-R67 -> -10553899
...

Sheet Puntos de Equilibrio
C3: Punto de Equilibrio Económico
D5: Cf | E5: =+'Gastos Fijos de Fabricación'!L27+'Gastos de Comercialización'!K43+'Gastos Adm y Finanzas'!F29+'Activo no Corriente'!F24 -> 16470613
D6: Pu | E6: =+Mercado!F18 -> 80000 | G6: Cvu TOTAL= | H6: =+E7+E8 -> 58611.111 | I6: $/u
D7: Cvu fab. | E7: =+'Costos Variables de Fabricación'!L26 -> 55411.111
D8: GCVu | E8: =+'Gastos de Comercialización'!L11 -> 3200
D10: Qo= | E10: =+E5/(E6-E7-E8) -> 770.05464 | F10: UNIDADES | G10: Io= | H10: =+E10*E6 -> 61604371 | I10: PESOS
D14: Q | E14: Ingreso Total | F14: Costo Fijo | G14: Costo Variable | H14: Costo Total | I14: Beneficio Total
D15: 0 | E15: =+D15*$E$6 -> 0 | F15: =+$E$5 -> 16470613 | G15: =+D15*H7 -> 0 | H15: =+G15+F15 -> 16470613 | I15: =+E15-F15-G15 -> -16470613
D16: 150 | E16: =+D16*$E$6 -> 12000000 | F16: =+$E$5 -> 16470613 | G16: =+D16*$H$6 -> 8791666.7 | H16: =+G16+F16 -> 25262280 | I16: =+E16-F16-G16 -> -13262280
D17: 500 | E17: =+D17*$E$6 -> 40000000 | F17: =+$E$5 -> 16470613 | G17: =+D17*$H$6 -> 29305556 | H17: =+G17+F17 -> 45776169 | I17: =+E17-F17-G17 -> -5776168.7
C18: Qo= | D18: =ROUNDUP(E10,0) -> 771 | E18: =+D18*$E$6 -> 61680000 | F18: =+$E$5 -> 16470613 | G18: =+D18*$H$6 -> 45189167 | H18: =+G18+F18 -> 61659780 | I18: =+E18-F18-G18 -> 20220.213
D19: 890 | E19: =+D19*$E$6 -> 71200000 | F19: =+$E$5 -> 16470613 | G19: =+D19*$H$6 -> 52163889 | H19: =+G19+F19 -> 68634502 | I19: =+E19-F19-G19 -> 2565498
D20: 2500 | E20: =+D20*$E$6 -> 200000000 | F20: =+$E$5 -> 16470613 | G20: =+D20*$H$6 -> 1.4652778e+08 | H20: =+G20+F20 -> 1.6299839e+08 | I20: =+E20-F20-G20 -> 37001609
D21: 3000 | E21: =+D21*$E$6 -> 240000000 | F21: =+$E$5 -> 16470613 | G21: =+D21*$H$6 -> 1.7583333e+08 | H21: =+G21+F21 -> 1.9230395e+08 | I21: =+E21-F21-G21 -> 47696054
D22: 3500 | E22: =+D22*$E$6 -> 280000000 | F22: =+$E$5 -> 16470613 | G22: =+D22*$H$6 -> 2.0513889e+08 | H22: =+G22+F22 -> 221609502 | I22: =+E22-F22-G22 -> 58390498
C23: Qmáx.= | D23: =Mercado!G6 -> 3600 | E23: =+D23*$E$6 -> 288000000 | F23: =+$E$5 -> 16470613 | G23: =+D23*$H$6 -> 211000000 | H23: =+G23+F23 -> 2.2747061e+08 | I23: =+E23-F23-G23 -> 60529387
C26: Qo/Qmáx.= | D26: =+D18/D23 -> 0.21416667 | E26: AÑO | F26: =+D26*Consideraciones!D9 -> 2.57 | G26: MESES | H26: =+Consideraciones!D10*D26 -> 78.170833 | I26: DÍAS
C29: Punto de Equilibrio Financiero
D31: Cf Erogable | E31: =+'Gastos Fijos de Fabricación'!L27+'Gastos de Comercialización'!K43+'Gastos Adm y Finanzas'!F29 -> 16460613
D32: Pu= | E32: =+E6 -> 80000 | G32: Cvu TOTAL= | H32: =+E33+E34 -> 58611.111 | I32: $/u
D33: Cvu fab. | E33: =+E7 -> 55411.111
D34: GCVu | E34: =+E8 -> 3200
D36: Qof= | E36: =+E31/(E32-E33-E34) -> 769.58711 | F36: UNIDADES | G36: Io= | H36: =+E36*E32 -> 61566969 | I36: PESOS
D39: Q | E39: Ingreso Total | F39: Costo Fijo | G39: Costo Variable | H39: Costo Total | I39: Beneficio Total
D40: 0 | E40: =+D40*$E$6 -> 0 | F40: =+$E$31 -> 16460613 | G40: =+D40*$H$32 -> 0 | H40: =+G40+F40 -> 16460613 | I40: =+E40-H40 -> -16460613
D41: 150 | E41: =+D41*$E$6 -> 12000000 | F41: =+$E$31 -> 16460613 | G41: =+D41*$H$32 -> 8791666.7 | H41: =+G41+F41 -> 25252280 | I41: =+E41-H41 -> -13252280
D42: 500 | E42: =+D42*$E$6 -> 40000000 | F42: =+$E$31 -> 16460613 | G42: =+D42*$H$32 -> 29305556 | H42: =+G42+F42 -> 45766169 | I42: =+E42-H42 -> -5766168.7
D43: 600 | E43: =+D43*$E$6 -> 48000000 | F43: =+$E$31 -> 16460613 | G43: =+D43*$H$32 -> 35166667 | H43: =+G43+F43 -> 51627280 | I43: =+E43-H43 -> -3627279.8
C44: Qof= | D44: =ROUNDUP(E36,0) -> 770 | E44: =+D44*$E$6 -> 61600000 | F44: =+$E$31 -> 16460613 | G44: =+D44*$H$32 -> 45130556 | H44: =+G44+F44 -> 61591169 | I44: =+E44-H44 -> 8831.3244
D45: 890 | E45: =+D45*$E$6 -> 71200000 | F45: =+$E$31 -> 16460613 | G45: =+D45*$H$32 -> 52163889 | H45: =+G45+F45 -> 68624502 | I45: =+E45-H45 -> 2575498
D46: 1000 | E46: =+D46*$E$6 -> 80000000 | F46: =+$E$31 -> 16460613 | G46: =+D46*$H$32 -> 58611111 | H46: =+G46+F46 -> 75071724 | I46: =+E46-H46 -> 4928275.8
D47: 1500 | E47: =+D47*$E$6 -> 120000000 | F47: =+$E$31 -> 16460613 | G47: =+D47*$H$32 -> 87916667 | H47: =+G47+F47 -> 1.0437728e+08 | I47: =+E47-H47 -> 15622720
D48: 2500 | E48: =+D48*$E$6 -> 200000000 | F48: =+$E$31 -> 16460613 | G48: =+D48*$H$32 -> 1.4652778e+08 | H48: =+G48+F48 -> 1.6298839e+08 | I48: =+E48-H48 -> 37011609
C49: Qmáx.= | D49: =Mercado!G6 -> 3600 | E49: =+D49*$E$6 -> 288000000 | F49: =+$E$31 -> 16460613 | G49: =+D49*$H$32 -> 211000000 | H49: =+G49+F49 -> 2.2746061e+08 | I49: =+E49-H49 -> 60539387
C52: Qof/Qmáx.= | D52: =+D44/D49 -> 0.21388889 | E52: AÑO | F52: =+D52*Consideraciones!D9 -> 2.5666667 | G52: MESES | H52: =+Consideraciones!D10*D52 -> 78.069444 | I52: DÍAS
